<?xml version="1.0" ?>
<robot name="baxter" xmlns:xacro="http://www.ros.org/wiki/xacro">
  <xacro:arg name="gazebo" default="false"/>
  <xacro:if value="$(arg gazebo)">
    <!-- Gazebo Tags -->
    <xacro:include filename="$(find baxter_camera)/urdf/baxter_base/baxter_base.gazebo.xacro" />
  </xacro:if>
  <link name="base">
  </link>
  <link name="torso">
    <visual>
      <origin rpy="0 0 0" xyz="0 0 0"/>
      <geometry>
        <mesh filename="package://baxter_camera/meshes/torso/base_link.DAE"/>
      </geometry>
      <material name="darkgray">
        <color rgba=".2 .2 .2 1"/>
      </material>
    </visual>
    <collision>
      <origin rpy="0 0 0" xyz="0 0 0"/>
      <geometry>
        <mesh filename="package://baxter_camera/meshes/torso/base_link_collision.DAE"/>
      </geometry>
    </collision>
    <inertial>
      <origin rpy="0 0 0" xyz="0.000000 0.000000 0.000000"/>
      <mass value="35.336455"/>
      <inertia ixx="1.849155" ixy="-0.000354" ixz="-0.154188" iyy="1.662671" iyz="0.003292" izz="0.802239"/>
    </inertial>
  </link>
  <joint name="torso_t0" type="fixed">
    <origin rpy="0 0 0" xyz="0 0 0"/>
    <parent link="base"/>
    <child link="torso"/>
    <limit effort="50000" lower="-3.01" upper="3.01" velocity="10000"/>
  </joint>
  <link name="left_torso_itb">
    <inertial>
      <origin rpy="0 0 0" xyz="0.000000 0.000000 0.000000"/>
      <mass value="0.0001"/>
      <inertia ixx="1e-08" ixy="0" ixz="0" iyy="1e-08" iyz="0" izz="1e-08"/>
    </inertial>
  </link>
  <joint name="left_torso_itb_fixed" type="fixed">
    <origin rpy="-1.57079632679 3.1415 0" xyz="-0.08897 0.15593 0.389125"/>
    <parent link="torso"/>
    <child link="left_torso_itb"/>
  </joint>
  <link name="right_torso_itb">
    <inertial>
      <origin rpy="0 0 0" xyz="0.000000 0.000000 0.000000"/>
      <mass value="0.0001"/>
      <inertia ixx="1e-08" ixy="0" ixz="0" iyy="1e-08" iyz="0" izz="1e-08"/>
    </inertial>
  </link>
  <joint name="right_torso_itb_fixed" type="fixed">
    <origin rpy="1.57079632679 0 0" xyz="-0.08897 -0.15593 0.389125"/>
    <parent link="torso"/>
    <child link="right_torso_itb"/>
  </joint>
  <link name="head">
    <visual>
      <origin rpy="0 0 0" xyz="0 0 0.00953"/>
      <geometry>
        <mesh filename="package://baxter_camera/meshes/head/H0.DAE"/>
      </geometry>
      <material name="darkgray">
        <color rgba=".2 .2 .2 1"/>
      </material>
    </visual>
    <collision>
      <origin rpy="0 0 0" xyz="0.0 0 0.0"/>
      <geometry>
        <sphere radius="0.001"/>
      </geometry>
    </collision>
    <inertial>
      <origin rpy="0 0 0" xyz="0 0 0"/>
      <mass value="0.547767"/>
      <inertia ixx="0.004641" ixy="0.000159" ixz="0.000242" iyy="0.003295" iyz="-0.001324" izz="0.003415"/>
    </inertial>
  </link>
  <joint name="head_pan" type="revolute">
    <origin rpy="0 0 0" xyz="0.06 0 0.4"/>
    <axis xyz="0 0 1"/>
    <parent link="torso"/>
    <child link="head"/>
    <limit effort="50000" lower="-1.3963" upper="1.3963" velocity="10000"/>
    <dynamics damping="0.7" friction="0.0"/>
  </joint>
</robot>
