<?xml version="1.0"?>
<robot xmlns:xacro="http://www.ros.org/wiki/xacro">
    <xacro:macro name="robotiq_handE" params="parent *origin">
        <material name="gray">
            <color rgba="0.5 0.5 0.5 2.0"/>
        </material>
        <material name="black">
            <color rgba="1.0 1.0 1.0 2.0"/>
        </material>
        <joint name="body_joint" type="fixed">
            <parent link="${parent}"/>
            <child link="body_link"/>
            <xacro:insert_block name="origin"/>  
        </joint>
        <link name="body_link">
            <inertial>
                <origin xyz="0.0 0.0 0.0" />
                <mass value="0.63387"/>
                <inertia ixx = "0.000002" ixy = "0.000000" ixz = "0.000000"
                    iyx = "0.000000" iyy = "0.000005" iyz = "0.000000"
                    izx = "0.000000" izy = "0.000000" izz = "0.000006" />
            </inertial>
            <visual>   
                <geometry>
                    <mesh filename="package://new_gripper/meshes/body.dae"/>
                </geometry>
            
                <!--origin xyz="0.086 0 0" rpy="0.0 ${pi/2} 0.0"/-->      
            </visual>
            <collision>
               <!--origin xyz="0.086 0 0" rpy="0.0 ${pi/2} 0.0"/-->
                <geometry>
                    <mesh filename="package://new_gripper/meshes/body.dae"/>
                </geometry>
            </collision>
        </link>
        <gazebo reference="body_link">
            <material>Gazebo/Black</material>
        
        </gazebo>
        <joint name="finger1_joint" type="prismatic">
            <parent link="body_link"/>
            <child link="finger_11_link"/>
            <origin rpy="${-pi/2} ${2*pi/2} 0.0" xyz="0.0 0.0 0.0"/>
            <axis xyz="0 0 -1"/>
            <limit effort="130" lower="0" upper="0.03" velocity="0.15"/>
        </joint>
        <link name="finger_11_link">
            <inertial>
                <origin xyz="0.0 0.0 0.0" />
                <mass value="0.03804"/>
                <inertia ixx = "0.000002" ixy = "0.000000" ixz = "0.000000"
                        iyx = "0.000000" iyy = "0.000005" iyz = "0.000000"
                        izx = "0.000000" izy = "0.000000" izz = "0.000006" />
            </inertial>
            <visual>
                <geometry>
                    <mesh filename="package://new_gripper/meshes/finger_11.dae"/>
                </geometry>
                <material name="gray" />
                <!--origin rpy="${pi/2} ${-pi/2} ${pi}" xyz="0.086 0 0"/-->
            </visual>
            <collision>
                <!--origin rpy="${pi/2} ${-pi/2} ${pi}" xyz="0.086 0 0"/-->
                <geometry>
                    <mesh filename="package://new_gripper/meshes/finger_11.dae"/>
                </geometry>
            </collision>
        </link>
        <gazebo reference="finger_11_link">
            <material>Gazebo/Grey</material>
           
        </gazebo>
    
        <!--joint name="finger2_joint" type="fixed">
            <parent link="body_link"/>
            <child link="finger_22_link"/>
            <origin rpy="${-pi/2} ${2*pi/2} 0.0" xyz="0.0 0.0 0.0"/>
        </joint-->
        <joint name="finger2_joint" type="prismatic">
            <parent link="body_link"/>
            <child link="finger_22_link"/>
            <origin xyz="${-pi/2} ${2*pi/2} 0.0" rpy="0.0 0.0 0.0"/>
            <axis xyz="0 0 1"/>
            <limit effort="130" lower="0" upper="0.03" velocity="0.15"/>
            <mimic joint="finger1_joint"/>
            
        </joint>
        <link name="finger_22_link">
            <inertial>
                <origin xyz="0.0 0.0 0.0" />
                <!--origin rpy="0 0 0" xyz="-0.02262 0.00759 0.00738"/-->
                <mass value="0.03804"/>
                <inertia ixx = "0.000002" ixy = "0.000000" ixz = "0.000000"
                        iyx = "0.000000" iyy = "0.000005" iyz = "0.000000"
                        izx = "0.000000" izy = "0.000000" izz = "0.000006" />
            </inertial>
            <visual>
                <geometry>
                    <mesh filename="package://new_gripper/meshes/finger_22.dae"/>
                </geometry>
                <material name="gray" />
                <!--origin rpy="${-pi/2} ${3*pi/2} 0.0" xyz="0.086 0.02 0.0"/-->
            </visual>
            <collision>
                <!--origin rpy="${-pi/2} ${3*pi/2} 0.0" xyz="0.086 0.02 0.0"/-->
                <geometry>
                    <mesh filename="package://new_gripper/meshes/finger_22.dae"/>
                </geometry>
            </collision>
        </link>
        <gazebo reference="finger_22_link">
            <material>Gazebo/Grey</material>
            
        </gazebo>
        <gazebo>
            <!--plugin name="ros_control" filename="libgazebo_ros_control.so">
            </plugin-->
             <plugin filename="libroboticsgroup_gazebo_mimic_joint_plugin.so" name="mimic">
                <joint>finger1_joint</joint>
                <mimicJoint>finger2_joint</mimicJoint>
                <multiplier>1.0</multiplier>
            </plugin>
        </gazebo>
        <transmission name="hardware_trans_1">  
            <type>trainsmission_interface/SimpleTransmission</type>
            <joint name="finger1_joint">
                <hardwareInterface>EffortJointInterface</hardwareInterface>   
            </joint>     
            <actuator name="finger1_actuator">
                <mechanicalReduction>1</mechanicalReduction>
            </actuator>  
        </transmission>
    </xacro:macro>

</robot>